
* This time around executing our code we get the following:

	```
	..F
	======================================================================
	FAIL: test_003_invalid_type_raises_error (__main__.HelperFunctionTests)
	----------------------------------------------------------------------
	Traceback (most recent call last):
	  File "/Users/kecorbin/Library/Preferences/PyCharm50/scratches/scratch_1", line 41, in test_003_invalid_type_raises_error
	    test = doubler('2')
	AssertionError: TypeError not raised
	
	----------------------------------------------------------------------
	Ran 3 tests in 0.001s
	
	FAILED (failures=1)
	```

